<?xml version="1.0" encoding="UTF-8"?>
<robot name="ur">

  <transmission name="shoulder_pan_trans">
    <type>transmission_interface/SimpleTransmission</type>
    <joint name="shoulder_pan_joint">
      <hardwareInterface>hardware_interface/PositionJointInterface</hardwareInterface>
    </joint>
    <actuator name="shoulder_pan_motor">
      <mechanicalReduction>1</mechanicalReduction>
    </actuator>
  </transmission>

  <transmission name="shoulder_lift_trans">
    <type>transmission_interface/SimpleTransmission</type>
    <joint name="shoulder_lift_joint">
      <hardwareInterface>hardware_interface/PositionJointInterface</hardwareInterface>
    </joint>
    <actuator name="shoulder_lift_motor">
      <mechanicalReduction>1</mechanicalReduction>
    </actuator>
  </transmission>

  <transmission name="elbow_trans">
    <type>transmission_interface/SimpleTransmission</type>
    <joint name="elbow_joint">
      <hardwareInterface>hardware_interface/PositionJointInterface</hardwareInterface>
    </joint>
    <actuator name="elbow_motor">
      <mechanicalReduction>1</mechanicalReduction>
    </actuator>
  </transmission>

  <transmission name="wrist_1_trans">
    <type>transmission_interface/SimpleTransmission</type>
    <joint name="wrist_1_joint">
      <hardwareInterface>hardware_interface/PositionJointInterface</hardwareInterface>
    </joint>
    <actuator name="wrist_1_motor">
      <mechanicalReduction>1</mechanicalReduction>
    </actuator>
  </transmission>

  <transmission name="wrist_2_trans">
    <type>transmission_interface/SimpleTransmission</type>
    <joint name="wrist_2_joint">
      <hardwareInterface>hardware_interface/PositionJointInterface</hardwareInterface>
    </joint>
    <actuator name="wrist_2_motor">
      <mechanicalReduction>1</mechanicalReduction>
    </actuator>
  </transmission>

  <transmission name="wrist_3_trans">
    <type>transmission_interface/SimpleTransmission</type>
    <joint name="wrist_3_joint">
      <hardwareInterface>hardware_interface/PositionJointInterface</hardwareInterface>
    </joint>
    <actuator name="wrist_3_motor">
      <mechanicalReduction>1</mechanicalReduction>
    </actuator>
  </transmission>

  <link name="world"/>

  <link name="base_link"/>
  <link name="base_link_inertia">
    <visual>
      <origin xyz="0 0 0" rpy="0 0 3.141592653589793"/>
      <geometry>
        <mesh filename="package://ur_description/meshes/ur5e/visual/base.dae"/>
      </geometry>
      <material name="LightGrey">
        <color rgba="0.7 0.7 0.7 1.0"/>
      </material>
    </visual>
    <collision>
      <origin xyz="0 0 0" rpy="0 0 3.141592653589793"/>
      <geometry>
        <mesh filename="package://ur_description/meshes/ur5e/collision/base.stl"/>
      </geometry>
    </collision>
    <inertial>
      <origin xyz="0 0 0" rpy="0 0 0"/>
      <mass value="4.0"/>
      <inertia ixx="0.00443333156" ixy="0.0" ixz="0.0" iyy="0.00443333156" iyz="0.0" izz="0.0072"/>
    </inertial>
  </link>

  <link name="shoulder_link">
    <visual>
      <origin xyz="0 0 0" rpy="0 0 3.141592653589793"/>
      <geometry>
        <mesh filename="package://ur_description/meshes/ur5e/visual/shoulder.dae"/>
      </geometry>
      <material name="LightGrey">
        <color rgba="0.7 0.7 0.7 1.0"/>
      </material>
    </visual>
    <collision>
      <origin xyz="0 0 0" rpy="0 0 3.141592653589793"/>
      <geometry>
        <mesh filename="package://ur_description/meshes/ur5e/collision/shoulder.stl"/>
      </geometry>
    </collision>
    <inertial>
      <origin xyz="0 0 0" rpy="0 0 0"/>
      <mass value="3.7"/>
      <inertia ixx="0.010267495893" ixy="0.0" ixz="0.0" iyy="0.010267495893" iyz="0.0" izz="0.00666"/>
    </inertial>
  </link>

  <link name="upper_arm_link">
    <visual>
      <origin xyz="0 0 0.138" rpy="1.5707963267948966 0 -1.5707963267948966"/>
      <geometry>
        <mesh filename="package://ur_description/meshes/ur5e/visual/upperarm.dae"/>
      </geometry>
      <material name="LightGrey">
        <color rgba="0.7 0.7 0.7 1.0"/>
      </material>
    </visual>
    <collision>
      <origin xyz="0 0 0.138" rpy="1.5707963267948966 0 -1.5707963267948966"/>
      <geometry>
        <mesh filename="package://ur_description/meshes/ur5e/collision/upperarm.stl"/>
      </geometry>
    </collision>
    <inertial>
      <origin xyz="-0.2125 0.0 0.138" rpy="0 1.5707963267948966 0"/>
      <mass value="8.393"/>
      <inertia ixx="0.1338857818623325" ixy="0.0" ixz="0.0" iyy="0.1338857818623325" iyz="0.0" izz="0.0151074"/>
    </inertial>
  </link>

  <link name="forearm_link">
    <visual>
      <origin xyz="0 0 0.007" rpy="1.5707963267948966 0 -1.5707963267948966"/>
      <geometry>
        <mesh filename="package://ur_description/meshes/ur5e/visual/forearm.dae"/>
      </geometry>
      <material name="LightGrey">
        <color rgba="0.7 0.7 0.7 1.0"/>
      </material>
    </visual>
    <collision>
      <origin xyz="0 0 0.007" rpy="1.5707963267948966 0 -1.5707963267948966"/>
      <geometry>
        <mesh filename="package://ur_description/meshes/ur5e/collision/forearm.stl"/>
      </geometry>
    </collision>
    <inertial>
      <origin xyz="-0.1961 0.0 0.007" rpy="0 1.5707963267948966 0"/>
      <mass value="2.275"/>
      <inertia ixx="0.031209355099586295" ixy="0.0" ixz="0.0" iyy="0.031209355099586295" iyz="0.0" izz="0.004095"/>
    </inertial>
  </link>

  <link name="wrist_1_link">
    <visual>
      <origin xyz="0 0 -0.127" rpy="1.5707963267948966 0 0"/>
      <geometry>
        <mesh filename="package://ur_description/meshes/ur5e/visual/wrist1.dae"/>
      </geometry>
      <material name="LightGrey">
        <color rgba="0.7 0.7 0.7 1.0"/>
      </material>
    </visual>
    <collision>
      <origin xyz="0 0 -0.127" rpy="1.5707963267948966 0 0"/>
      <geometry>
        <mesh filename="package://ur_description/meshes/ur5e/collision/wrist1.stl"/>
      </geometry>
    </collision>
    <inertial>
      <origin xyz="0 0 0" rpy="0 0 0"/>
      <mass value="1.219"/>
      <inertia ixx="0.0025598989760400002" ixy="0.0" ixz="0.0" iyy="0.0025598989760400002" iyz="0.0" izz="0.0021942"/>
    </inertial>
  </link>

  <link name="wrist_2_link">
    <visual>
      <origin xyz="0 0 -0.0997" rpy="0 0 0"/>
      <geometry>
        <mesh filename="package://ur_description/meshes/ur5e/visual/wrist2.dae"/>
      </geometry>
      <material name="LightGrey">
        <color rgba="0.7 0.7 0.7 1.0"/>
      </material>
    </visual>
    <collision>
      <origin xyz="0 0 -0.0997" rpy="0 0 0"/>
      <geometry>
        <mesh filename="package://ur_description/meshes/ur5e/collision/wrist2.stl"/>
      </geometry>
    </collision>
    <inertial>
      <origin xyz="0 0 0" rpy="0 0 0"/>
      <mass value="1.219"/>
      <inertia ixx="0.0025598989760400002" ixy="0.0" ixz="0.0" iyy="0.0025598989760400002" iyz="0.0" izz="0.0021942"/>
    </inertial>
  </link>

  <link name="wrist_3_link">
    <visual>
      <origin xyz="0 0 -0.0989" rpy="1.5707963267948966 0 0"/>
      <geometry>
        <mesh filename="package://ur_description/meshes/ur5e/visual/wrist3.dae"/>
      </geometry>
      <material name="LightGrey">
        <color rgba="0.7 0.7 0.7 1.0"/>
      </material>
    </visual>
    <collision>
      <origin xyz="0 0 -0.0989" rpy="1.5707963267948966 0 0"/>
      <geometry>
        <mesh filename="package://ur_description/meshes/ur5e/collision/wrist3.stl"/>
      </geometry>
    </collision>
    <inertial>
      <origin xyz="0.0 0.0 -0.0229" rpy="0 0 0"/>
      <mass value="0.1879"/>
      <inertia ixx="9.890410052167731e-05" ixy="0.0" ixz="0.0" iyy="9.890410052167731e-05" iyz="0.0" izz="0.0001321171875"/>
    </inertial>
  </link>

  <joint name="world_joint" type="fixed">
    <parent link="world"/>
    <child link="base_link"/>
    <origin xyz="0 0 0" rpy="0 0 0"/>
  </joint>

  <joint name="base_link-base_link_inertia" type="fixed">
    <parent link="base_link"/>
    <child link="base_link_inertia"/>
    <origin xyz="0 0 0" rpy="0 0 3.141592653589793"/>
  </joint>

  <joint name="shoulder_pan_joint" type="revolute">
    <parent link="base_link_inertia"/>
    <child link="shoulder_link"/>
    <origin xyz="0 0 0.1625" rpy="0 0 0"/>
    <axis xyz="0 0 1"/>
    <limit lower="-6.283185307179586" upper="6.283185307179586" effort="150.0" velocity="3.141592653589793"/>
    <dynamics damping="0" friction="0"/>
  </joint>

  <joint name="shoulder_lift_joint" type="revolute">
    <parent link="shoulder_link"/>
    <child link="upper_arm_link"/>
    <origin xyz="0 0 0" rpy="1.570796327 0 0"/>
    <axis xyz="0 0 1"/>
    <limit lower="-6.283185307179586" upper="6.283185307179586" effort="150.0" velocity="3.141592653589793"/>
    <dynamics damping="0" friction="0"/>
  </joint>

  <joint name="elbow_joint" type="revolute">
    <parent link="upper_arm_link"/>
    <child link="forearm_link"/>
    <origin xyz="-0.425 0 0" rpy="0 0 0"/>
    <axis xyz="0 0 1"/>
    <limit lower="-3.141592653589793" upper="3.141592653589793" effort="150.0" velocity="3.141592653589793"/>
    <dynamics damping="0" friction="0"/>
  </joint>

  <joint name="wrist_1_joint" type="revolute">
    <parent link="forearm_link"/>
    <child link="wrist_1_link"/>
    <origin xyz="-0.3922 0 0.1333" rpy="0 0 0"/>
    <axis xyz="0 0 1"/>
    <limit lower="-6.283185307179586" upper="6.283185307179586" effort="28.0" velocity="3.141592653589793"/>
    <dynamics damping="0" friction="0"/>
  </joint>

  <joint name="wrist_2_joint" type="revolute">
    <parent link="wrist_1_link"/>
    <child link="wrist_2_link"/>
    <origin xyz="0 -0.0997 -2.044881182297852e-11" rpy="1.570796327 0 0"/>
    <axis xyz="0 0 1"/>
    <limit lower="-6.283185307179586" upper="6.283185307179586" effort="28.0" velocity="3.141592653589793"/>
    <dynamics damping="0" friction="0"/>
  </joint>

  <joint name="wrist_3_joint" type="revolute">
    <parent link="wrist_2_link"/>
    <child link="wrist_3_link"/>
    <origin xyz="0 0.0996 -2.042830148012698e-11" rpy="1.570796326589793 3.141592653589793 3.141592653589793"/>
    <axis xyz="0 0 1"/>
    <limit lower="-6.283185307179586" upper="6.283185307179586" effort="28.0" velocity="3.141592653589793"/>
    <dynamics damping="0" friction="0"/>
  </joint>

  <link name="base"/>
  <joint name="base_link-base_fixed_joint" type="fixed">
    <parent link="base_link"/>
    <child link="base"/>
    <origin xyz="0 0 0" rpy="0 0 3.141592653589793"/>
  </joint>

  <link name="flange"/>
  <joint name="wrist_3-flange" type="fixed">
    <parent link="wrist_3_link"/>
    <child link="flange"/>
    <origin xyz="0 0 0" rpy="0 -1.5707963267948966 -1.5707963267948966"/>
  </joint>

  <link name="tool0"/>
  <joint name="flange-tool0" type="fixed">
    <parent link="flange"/>
    <child link="tool0"/>
    <origin xyz="0 0 0" rpy="1.5707963267948966 0 1.5707963267948966"/>
  </joint>

</robot>

